"""Critical scenario tests for Error Recovery System.

This test suite covers high-priority missing areas identified in the testing gap analysis:
1. Strategy implementation with complex failure scenarios
2. Retry logic with exponential backoff and circuit breakers
3. Fallback mechanisms when primary operations fail
4. Recovery orchestration and strategy coordination
5. Network error handling for S3 and external services
6. Process recovery for FFmpeg and RIFE failures
7. Concurrency and resource management under error conditions
"""

from enum import Enum
import threading
import time
from typing import Any, Never

import pytest

from goesvfi.core.error_decorators import with_retry
from goesvfi.pipeline.exceptions import FFmpegError, ProcessingError, RIFEError


class ErrorCategory(Enum):
    """Error categories for classification."""

    NETWORK = "network"
    FILE_NOT_FOUND = "file_not_found"
    PERMISSION = "permission"
    PROCESSING = "processing"
    EXTERNAL_TOOL = "external_tool"
    SYSTEM = "system"


class StructuredError(Exception):
    """Mock structured error for testing."""

    def __init__(
        self,
        message: str,
        category: ErrorCategory,
        details: dict | None = None,
        recovery_suggestion: str = "",
        *,
        is_recoverable: bool = True,
    ):
        super().__init__(message)
        self.category = category
        self.details = details or {}
        self.recovery_suggestion = recovery_suggestion
        self.is_recoverable = is_recoverable


class RecoveryStrategy:
    """Base recovery strategy interface."""

    def can_recover(self, error: StructuredError) -> bool:
        raise NotImplementedError

    def attempt_recovery(self, error: StructuredError) -> tuple[bool, str]:
        raise NotImplementedError


class RecoveryManager:
    """Mock recovery manager for testing."""

    def __init__(self) -> None:
        self.strategies: list[RecoveryStrategy] = []

    def add_strategy(self, strategy: RecoveryStrategy) -> None:
        self.strategies.append(strategy)

    def attempt_recovery(self, error: StructuredError) -> tuple[bool, str]:
        for strategy in self.strategies:
            if strategy.can_recover(error):
                return strategy.attempt_recovery(error)
        return False, "No recovery strategy available"


class TestErrorRecoveryCritical:
    """Critical scenario tests for error recovery system."""

    @pytest.fixture()
    @staticmethod
    def error_tracker() -> Any:
        """Create error tracking fixture for test validation.

        Returns:
            ErrorTracker: Instance for tracking errors and recovery attempts.
        """

        class ErrorTracker:
            def __init__(self) -> None:
                self.recovery_attempts: list[dict] = []
                self.retry_attempts: list[dict] = []
                self.fallback_attempts: list[dict] = []
                self.strategy_executions: list[dict] = []
                self.lock = threading.Lock()

            def track_recovery(self, strategy_name: str, *, success: bool, attempt_count: int) -> None:
                with self.lock:
                    self.recovery_attempts.append({
                        "strategy": strategy_name,
                        "success": success,
                        "attempts": attempt_count,
                        "timestamp": time.time(),
                    })

            def track_retry(self, function_name: str, attempt: int, delay: float, *, success: bool) -> None:
                with self.lock:
                    self.retry_attempts.append({
                        "function": function_name,
                        "attempt": attempt,
                        "delay": delay,
                        "success": success,
                        "timestamp": time.time(),
                    })

            def track_fallback(self, primary_failed: str, fallback_used: str, *, success: bool) -> None:
                with self.lock:
                    self.fallback_attempts.append({
                        "primary": primary_failed,
                        "fallback": fallback_used,
                        "success": success,
                        "timestamp": time.time(),
                    })

            def track_strategy_execution(self, strategy: str, input_error: str, output_result: str) -> None:
                with self.lock:
                    self.strategy_executions.append({
                        "strategy": strategy,
                        "input": input_error,
                        "output": output_result,
                        "timestamp": time.time(),
                    })

            def reset(self) -> None:
                with self.lock:
                    self.recovery_attempts.clear()
                    self.retry_attempts.clear()
                    self.fallback_attempts.clear()
                    self.strategy_executions.clear()

        return ErrorTracker()

    @staticmethod
    def test_strategy_implementation_complex_scenarios(error_tracker: Any) -> None:
        """Test recovery strategy implementation with complex failure scenarios."""
        # Split this complex test into smaller helper functions
        TestErrorRecoveryCritical._test_network_recovery_strategy(error_tracker)
        TestErrorRecoveryCritical._test_file_recovery_strategy(error_tracker)
        TestErrorRecoveryCritical._test_process_recovery_strategy(error_tracker)
        TestErrorRecoveryCritical._test_recovery_verification(error_tracker)

    @staticmethod
    def _test_network_recovery_strategy(error_tracker: Any) -> tuple[Any, list[tuple[str, str, str | None]]]:
        """Test network recovery strategy implementation."""

        # Create custom recovery strategies for testing
        class NetworkRecoveryStrategy:
            @staticmethod
            def can_recover(error: StructuredError) -> bool:
                return error.category == ErrorCategory.NETWORK

            @staticmethod
            def attempt_recovery(error: StructuredError) -> tuple[bool, str]:
                error_tracker.track_strategy_execution("network", str(error), "attempted")

                # Simulate network diagnostics and recovery
                if "connection timeout" in str(error).lower():
                    error_tracker.track_recovery("network_timeout", success=True, attempt_count=1)
                    return True, "Connection timeout resolved by increasing timeout values"
                if "dns resolution" in str(error).lower():
                    error_tracker.track_recovery("network_dns", success=True, attempt_count=1)
                    return True, "DNS resolution issues resolved"
                error_tracker.track_recovery("network_general", success=False, attempt_count=1)
                return False, "Network error could not be resolved"

        return NetworkRecoveryStrategy(), [
            (ErrorCategory.NETWORK, "Connection timeout to NOAA servers", "network_timeout"),
            (ErrorCategory.NETWORK, "DNS resolution failed for amazonaws.com", "network_dns"),
        ]

    @staticmethod
    def _test_file_recovery_strategy(error_tracker: Any) -> tuple[Any, list[tuple[str, str, str | None]]]:
        """Test file recovery strategy implementation."""

        class FileRecoveryStrategy:
            @staticmethod
            def can_recover(error: StructuredError) -> bool:
                return error.category in {ErrorCategory.FILE_NOT_FOUND, ErrorCategory.PERMISSION}

            @staticmethod
            def attempt_recovery(error: StructuredError) -> tuple[bool, str]:
                error_tracker.track_strategy_execution("file", str(error), "attempted")

                if error.category == ErrorCategory.FILE_NOT_FOUND:
                    # Simulate file recreation
                    error_tracker.track_recovery("file_recreation", success=True, attempt_count=1)
                    return True, "Missing file recreated successfully"
                if error.category == ErrorCategory.PERMISSION:
                    # Simulate permission fix
                    error_tracker.track_recovery("permission_fix", success=True, attempt_count=1)
                    return True, "File permissions corrected"
                error_tracker.track_recovery("file_general", success=False, attempt_count=1)
                return False, "File error could not be resolved"

        return FileRecoveryStrategy(), [
            (ErrorCategory.FILE_NOT_FOUND, "Configuration file missing", "file_recreation"),
            (ErrorCategory.PERMISSION, "Cannot write to output directory", "permission_fix"),
        ]

    @staticmethod
    def _test_process_recovery_strategy(error_tracker: Any) -> tuple[Any, list[tuple[str, str, str | None]]]:
        """Test process recovery strategy implementation."""

        class ProcessRecoveryStrategy:
            @staticmethod
            def can_recover(error: StructuredError) -> bool:
                return error.category == ErrorCategory.EXTERNAL_TOOL

            @staticmethod
            def attempt_recovery(error: StructuredError) -> tuple[bool, str]:
                error_tracker.track_strategy_execution("process", str(error), "attempted")

                if "ffmpeg" in str(error).lower():
                    error_tracker.track_recovery("ffmpeg_recovery", success=True, attempt_count=2)
                    return True, "FFmpeg process restarted with different parameters"
                if "rife" in str(error).lower():
                    error_tracker.track_recovery("rife_recovery", success=True, attempt_count=2)
                    return True, "RIFE model loaded with fallback configuration"
                error_tracker.track_recovery("process_general", success=False, attempt_count=1)
                return False, "External tool error could not be resolved"

        return ProcessRecoveryStrategy(), [
            (ErrorCategory.EXTERNAL_TOOL, "FFmpeg encoding failed with exit code 1", "ffmpeg_recovery"),
            (ErrorCategory.EXTERNAL_TOOL, "RIFE model could not be loaded", "rife_recovery"),
        ]

    @staticmethod
    def _test_recovery_verification(error_tracker: Any) -> None:
        """Test recovery verification and coordination."""
        network_strategy, network_scenarios = TestErrorRecoveryCritical._test_network_recovery_strategy(error_tracker)
        file_strategy, file_scenarios = TestErrorRecoveryCritical._test_file_recovery_strategy(error_tracker)
        process_strategy, process_scenarios = TestErrorRecoveryCritical._test_process_recovery_strategy(error_tracker)

        # Create a simple recovery manager for testing
        strategies: list[Any] = [network_strategy, file_strategy, process_strategy]

        # Test complex error scenarios
        test_scenarios = [
            *network_scenarios,
            *file_scenarios,
            *process_scenarios,
            (ErrorCategory.PROCESSING, "Unknown processing error", None),  # Should not be recoverable
        ]

        for category, message, expected_recovery in test_scenarios:
            # Create structured error
            error = StructuredError(
                message=message,
                category=category,
                details={"test_scenario": True},
                recovery_suggestion="Test recovery",
                is_recoverable=True,
            )

            # Attempt recovery using strategies
            success = False
            recovery_message = ""

            for strategy in strategies:
                if strategy.can_recover(error):
                    success, recovery_message = strategy.attempt_recovery(error)
                    break

            if expected_recovery:
                assert success, f"Recovery should succeed for {category.value}: {message}"
                assert len(recovery_message) > 0, "Recovery message should be provided"

                # Verify strategy was executed - map expected recovery to actual strategy names
                strategy_mapping = {
                    "network": "network",
                    "file": "file",
                    "permission": "file",  # permission_fix uses file strategy
                    "ffmpeg": "process",
                    "rife": "process",
                }
                strategy_name = strategy_mapping.get(expected_recovery.split("_")[0], expected_recovery.split("_")[0])
                strategy_executions = [e for e in error_tracker.strategy_executions if strategy_name in e["strategy"]]
                assert len(strategy_executions) > 0, f"Strategy should be executed for {expected_recovery}"

            else:
                assert not success, f"Recovery should fail for unsupported category: {category.value}"

        # Verify all expected recoveries were tracked
        expected_recoveries = [
            "network_timeout",
            "network_dns",
            "file_recreation",
            "permission_fix",
            "ffmpeg_recovery",
            "rife_recovery",
        ]
        actual_recoveries = [r["strategy"] for r in error_tracker.recovery_attempts if r["success"]]

        for expected in expected_recoveries:
            assert expected in actual_recoveries, f"Expected recovery '{expected}' was not executed"

    @staticmethod
    def test_retry_logic_exponential_backoff(error_tracker: Any) -> None:
        """Test retry logic with exponential backoff and failure scenarios."""
        call_count = 0
        max_delay_seen = 0.0

        def track_retry_attempt(attempt: int, exception: Exception) -> None:
            # Calculate the expected delay for this attempt (not passed by decorator)
            expected_delay = 0.1 * (2.0 ** (attempt - 1))
            nonlocal max_delay_seen
            max_delay_seen = max(max_delay_seen, expected_delay)
            error_tracker.track_retry("test_function", attempt, expected_delay, success=False)
            _ = exception  # Use the exception parameter

        # Test with exponential backoff
        @with_retry(
            max_attempts=5,
            delay=0.1,
            backoff_factor=2.0,
            exceptions=(ValueError, ConnectionError),
            on_retry=track_retry_attempt,
        )
        def failing_function_exponential() -> str:
            nonlocal call_count
            call_count += 1

            if call_count <= 3:
                if call_count == 1:
                    msg = "First failure"
                    raise ValueError(msg)
                if call_count == 2:
                    msg = "Second failure"
                    raise ConnectionError(msg)
                # Third failure with retryable exception, should succeed on 4th attempt
                msg = "Third failure"
                raise ValueError(msg)

            return "Success"

        # Should eventually succeed
        result = failing_function_exponential()
        assert result == "Success"

        # Verify exponential backoff occurred
        retry_delays = [r["delay"] for r in error_tracker.retry_attempts]
        assert len(retry_delays) >= 2, "Should have multiple retry attempts"

        # Check exponential progression (0.1, 0.2, 0.4...)
        expected_delays = [0.1 * (2.0**i) for i in range(len(retry_delays))]
        for i, (actual, expected) in enumerate(zip(retry_delays, expected_delays, strict=False)):
            assert abs(actual - expected) < 0.01, f"Retry {i}: expected ~{expected}s, got {actual}s"

        # Test max attempts exhaustion
        error_tracker.reset()
        call_count = 0

        def track_retry_attempt_2(attempt: int, exception: Exception) -> None:
            expected_delay = 0.05 * (2.0 ** (attempt - 1))
            error_tracker.track_retry("test_function", attempt, expected_delay, success=False)
            _ = exception  # Use the exception parameter

        @with_retry(
            max_attempts=3, delay=0.05, backoff_factor=2.0, exceptions=(ValueError,), on_retry=track_retry_attempt_2
        )
        def always_failing_function() -> Never:
            nonlocal call_count
            call_count += 1
            msg = f"Failure {call_count}"
            raise ValueError(msg)

        # Should exhaust retries and raise the last exception
        with pytest.raises(ValueError, match="Failure 3"):
            always_failing_function()

        # Verify all retries were attempted
        assert call_count == 3, f"Should attempt exactly 3 times, got {call_count}"
        assert len(error_tracker.retry_attempts) == 2, "Should track 2 retry attempts (not including initial attempt)"

    @staticmethod
    def test_fallback_mechanisms_chain(error_tracker: Any) -> None:
        """Test fallback mechanisms when primary operations fail."""

        class DataSource:
            def __init__(self, name: str, fail_on_attempts: list[int] | None = None):
                self.name = name
                self.attempt_count = 0
                self.fail_on_attempts = fail_on_attempts or []

            def fetch_data(self) -> str:
                self.attempt_count += 1
                if self.attempt_count in self.fail_on_attempts:
                    msg = f"{self.name} source unavailable"
                    raise ConnectionError(msg)
                return f"Data from {self.name}"

        class FallbackDataManager:
            def __init__(self) -> None:
                self.primary = DataSource("CDN", fail_on_attempts=[1, 2])
                self.secondary = DataSource("S3", fail_on_attempts=[1])
                self.tertiary = DataSource("Local Cache")

            def fetch_with_fallback(self):
                sources = [("primary", self.primary), ("secondary", self.secondary), ("tertiary", self.tertiary)]

                for source_name, source in sources:
                    try:
                        result = source.fetch_data()
                        error_tracker.track_fallback("none", source_name, success=True)
                        return result, source_name
                    except Exception:
                        error_tracker.track_fallback(source_name, "next", success=False)
                        continue

                msg = "All fallback sources failed"
                raise RuntimeError(msg)

        manager = FallbackDataManager()

        # First attempt - CDN fails, S3 fails, Local Cache succeeds
        result, source_used = manager.fetch_with_fallback()
        assert result == "Data from Local Cache"
        assert source_used == "tertiary"

        # Verify fallback chain was followed
        fallback_attempts = error_tracker.fallback_attempts
        assert len(fallback_attempts) >= 2, "Should have attempted multiple fallbacks"

        # Check fallback progression
        failed_sources = [f["primary"] for f in fallback_attempts if not f["success"]]
        assert "primary" in failed_sources, "Primary CDN should have failed"
        assert "secondary" in failed_sources, "Secondary S3 should have failed"

        successful_fallback = [f for f in fallback_attempts if f["success"]]
        assert len(successful_fallback) > 0, "Should have successful fallback"
        assert successful_fallback[0]["fallback"] == "tertiary", "Should fallback to tertiary source"

    @staticmethod
    def test_process_recovery_ffmpeg_rife_failures(error_tracker: Any) -> None:
        """Test process recovery for FFmpeg and RIFE failures."""

        class ProcessRecoveryManager:
            def __init__(self) -> None:
                self.ffmpeg_retry_count = 0
                self.rife_retry_count = 0

            def run_ffmpeg_with_recovery(self, command: list[str], input_file: str) -> str | None:
                """Run FFmpeg with automatic recovery on failure."""
                max_attempts = 3

                for attempt in range(max_attempts):
                    try:
                        self.ffmpeg_retry_count += 1

                        # Simulate FFmpeg failures
                        if attempt == 0:
                            error_tracker.track_retry("ffmpeg", attempt + 1, 0.5, success=False)
                            raise FFmpegError(
                                message="Codec not found", command=" ".join(command), stderr="Codec not found"
                            )
                        if attempt == 1:
                            error_tracker.track_retry("ffmpeg", attempt + 1, 1.0, success=False)
                            raise FFmpegError(
                                message="Input file corrupted", command=" ".join(command), stderr="Input file corrupted"
                            )
                        # Success on third attempt
                        error_tracker.track_retry("ffmpeg", attempt + 1, 0.0, success=True)
                        error_tracker.track_recovery("ffmpeg_full_recovery", success=True, attempt_count=attempt + 1)
                        return "FFmpeg success with fallback codec"

                    except FFmpegError as e:
                        if attempt < max_attempts - 1:
                            # Try recovery strategies
                            if "codec not found" in e.stderr.lower():
                                command = self._modify_command_for_codec_fallback(command)
                                error_tracker.track_strategy_execution("ffmpeg_codec", str(e), "codec_fallback")
                            elif "corrupted" in e.stderr.lower():
                                error_tracker.track_strategy_execution("ffmpeg_input", str(e), "input_validation")

                            time.sleep(0.1 * (attempt + 1))  # Brief delay
                        else:
                            error_tracker.track_recovery(
                                "ffmpeg_full_recovery", success=False, attempt_count=max_attempts
                            )
                            raise
                return None

            def run_rife_with_recovery(self, model_path: str, input_images: list[str]) -> str | None:
                """Run RIFE with automatic recovery on failure."""
                max_attempts = 3

                for attempt in range(max_attempts):
                    try:
                        self.rife_retry_count += 1

                        # Simulate RIFE failures
                        if attempt == 0:
                            error_tracker.track_retry("rife", attempt + 1, 0.3, success=False)
                            msg = "CUDA out of memory"
                            raise RIFEError(msg)
                        if attempt == 1:
                            error_tracker.track_retry("rife", attempt + 1, 0.6, success=False)
                            msg = "Model file corrupted"
                            raise RIFEError(msg)
                        # Success on third attempt
                        error_tracker.track_retry("rife", attempt + 1, 0.0, success=True)
                        error_tracker.track_recovery("rife_full_recovery", success=True, attempt_count=attempt + 1)
                        return "RIFE success with CPU fallback"

                    except RIFEError as e:
                        if attempt < max_attempts - 1:
                            # Try recovery strategies
                            if "cuda out of memory" in str(e).lower():
                                error_tracker.track_strategy_execution("rife_memory", str(e), "cpu_fallback")
                            elif "corrupted" in str(e).lower():
                                error_tracker.track_strategy_execution("rife_model", str(e), "model_fallback")

                            time.sleep(0.1 * (attempt + 1))  # Brief delay
                        else:
                            error_tracker.track_recovery(
                                "rife_full_recovery", success=False, attempt_count=max_attempts
                            )
                            raise
                return None

            def _modify_command_for_codec_fallback(self, command: list[str]) -> list[str]:
                """Modify FFmpeg command to use fallback codec."""
                # Replace codec with fallback
                modified = command.copy()
                if "-c:v" in modified:
                    codec_index = modified.index("-c:v")
                    if codec_index + 1 < len(modified):
                        modified[codec_index + 1] = "libx264"  # Fallback codec
                return modified

        manager = ProcessRecoveryManager()

        # Test FFmpeg recovery
        ffmpeg_command = ["ffmpeg", "-i", "input.mp4", "-c:v", "h264_nvenc", "output.mp4"]
        result = manager.run_ffmpeg_with_recovery(ffmpeg_command, "input.mp4")
        assert result is not None and "success" in result.lower(), "FFmpeg should eventually succeed"
        assert manager.ffmpeg_retry_count == 3, "Should attempt FFmpeg 3 times"

        # Test RIFE recovery
        rife_result = manager.run_rife_with_recovery("/path/to/model", ["img1.png", "img2.png"])
        assert rife_result is not None and "success" in rife_result.lower(), "RIFE should eventually succeed"
        assert manager.rife_retry_count == 3, "Should attempt RIFE 3 times"

        # Verify recovery strategies were executed
        ffmpeg_strategies = [s for s in error_tracker.strategy_executions if "ffmpeg" in s["strategy"]]
        rife_strategies = [s for s in error_tracker.strategy_executions if "rife" in s["strategy"]]

        assert len(ffmpeg_strategies) >= 2, "Should execute FFmpeg recovery strategies"
        assert len(rife_strategies) >= 2, "Should execute RIFE recovery strategies"

        # Verify successful recoveries were tracked
        successful_recoveries = [r for r in error_tracker.recovery_attempts if r["success"]]
        recovery_types = [r["strategy"] for r in successful_recoveries]

        assert "ffmpeg_full_recovery" in recovery_types, "Should track successful FFmpeg recovery"
        assert "rife_full_recovery" in recovery_types, "Should track successful RIFE recovery"

    @staticmethod
    def test_concurrency_resource_management_under_errors(error_tracker: Any) -> None:
        """Test concurrency and resource management under error conditions."""
        import concurrent.futures

        class ConcurrentErrorProcessor:
            def __init__(self, max_workers: int = 4):
                self.max_workers = max_workers
                self.active_operations = 0
                self.operation_lock = threading.Lock()
                self.failure_rate = 0.3  # 30% of operations fail initially

            def process_with_error_handling(self, task_id: int) -> dict:
                """Process task with error handling and resource management."""
                with self.operation_lock:
                    self.active_operations += 1

                try:
                    # Simulate processing with potential errors
                    import random

                    if random.random() < self.failure_rate:
                        # Simulate different types of errors
                        error_types = [
                            ("network", ConnectionError("Network unavailable")),
                            ("resource", MemoryError("Insufficient memory")),
                            ("processing", ProcessingError("Data processing failed")),
                        ]

                        error_type, exception = random.choice(error_types)
                        error_tracker.track_retry(f"task_{task_id}", 1, 0.1, success=False)

                        # Attempt recovery
                        if error_type == "network":
                            time.sleep(0.1)  # Brief retry delay
                            error_tracker.track_recovery("network_retry", success=True, attempt_count=1)
                            return {"task_id": task_id, "result": "recovered_from_network_error", "attempts": 2}
                        if error_type == "resource":
                            # Reduce concurrent operations
                            error_tracker.track_recovery("resource_throttle", success=True, attempt_count=1)
                            return {"task_id": task_id, "result": "recovered_from_resource_error", "attempts": 2}
                        error_tracker.track_recovery("processing_retry", success=False, attempt_count=1)
                        raise exception
                    # Successful processing
                    error_tracker.track_retry(f"task_{task_id}", 1, 0.0, success=True)
                    return {"task_id": task_id, "result": "success", "attempts": 1}

                finally:
                    with self.operation_lock:
                        self.active_operations -= 1

        processor = ConcurrentErrorProcessor()

        # Process multiple tasks concurrently
        tasks = list(range(20))
        results = []
        errors = []

        with concurrent.futures.ThreadPoolExecutor(max_workers=processor.max_workers) as executor:
            # Submit all tasks
            future_to_task = {
                executor.submit(processor.process_with_error_handling, task_id): task_id for task_id in tasks
            }

            # Collect results as they complete
            for future in concurrent.futures.as_completed(future_to_task):
                task_id = future_to_task[future]
                try:
                    result = future.result()
                    results.append(result)
                except Exception as e:
                    errors.append({"task_id": task_id, "error": str(e)})

        # Verify concurrent processing with error recovery
        total_operations = len(results) + len(errors)
        assert total_operations == len(tasks), f"Should process all {len(tasks)} tasks"

        # Check that most operations succeeded (either immediately or after recovery)
        success_rate = len(results) / total_operations
        assert success_rate >= 0.7, f"Success rate should be at least 70%, got {success_rate:.2f}"

        # Verify error recovery was attempted
        recovery_attempts = error_tracker.recovery_attempts
        assert len(recovery_attempts) > 0, "Should have recovery attempts for concurrent failures"

        # Check resource management - no resource exhaustion
        resource_recoveries = [r for r in recovery_attempts if "resource" in r["strategy"]]
        if len(resource_recoveries) > 0:
            assert all(r["success"] for r in resource_recoveries), "Resource recovery should succeed"

        # Verify retry attempts were made
        retry_attempts = error_tracker.retry_attempts
        retry_count = len(retry_attempts)

        # Should have some retries but not excessive (good error handling)
        assert retry_count <= total_operations, "Retry count should be reasonable"

    @staticmethod
    def test_circuit_breaker_pattern_implementation(error_tracker: Any) -> None:
        """Test circuit breaker pattern for preventing cascade failures."""

        class CircuitBreaker:
            def __init__(self, failure_threshold: int = 5, recovery_timeout: float = 2.0):
                self.failure_threshold = failure_threshold
                self.recovery_timeout = recovery_timeout
                self.failure_count = 0
                self.last_failure_time: float | None = None
                self.state = "CLOSED"  # CLOSED, OPEN, HALF_OPEN

            def call(self, func: Any, *args: Any, **kwargs: Any) -> Any:
                if self.state == "OPEN":
                    if self.last_failure_time and time.time() - self.last_failure_time < self.recovery_timeout:
                        error_tracker.track_fallback("circuit_breaker", "blocked_call", success=False)
                        msg = "Circuit breaker is OPEN"
                        raise RuntimeError(msg)
                    self.state = "HALF_OPEN"
                    error_tracker.track_recovery("circuit_breaker_half_open", success=True, attempt_count=1)

                try:
                    result = func(*args, **kwargs)
                    # Success - reset failure count
                    if self.state == "HALF_OPEN":
                        self.state = "CLOSED"
                        self.failure_count = 0
                        error_tracker.track_recovery("circuit_breaker_closed", success=True, attempt_count=1)
                    return result

                except Exception:
                    self.failure_count += 1
                    self.last_failure_time = time.time()

                    if self.failure_count >= self.failure_threshold:
                        self.state = "OPEN"
                        error_tracker.track_recovery(
                            "circuit_breaker_opened", success=True, attempt_count=self.failure_count
                        )

                    error_tracker.track_retry("circuit_breaker_call", self.failure_count, 0.0, success=False)
                    raise

        # Create a service that fails frequently
        class UnstableService:
            def __init__(self) -> None:
                self.call_count = 0

            def make_request(self) -> str:
                self.call_count += 1
                # Fail for first 5 calls to trigger circuit opening, then succeed
                if self.call_count <= 5:
                    msg = f"Service failure {self.call_count}"
                    raise ConnectionError(msg)
                return f"Success on call {self.call_count}"

        service = UnstableService()
        circuit_breaker = CircuitBreaker(failure_threshold=5, recovery_timeout=0.5)

        # Test circuit breaker behavior
        results = []
        exceptions = []

        # First phase: accumulate failures until circuit opens
        for i in range(10):
            try:
                result = circuit_breaker.call(service.make_request)
                results.append(result)
            except (ConnectionError, RuntimeError) as e:
                exceptions.append(str(e))

            # Small delay to test timing
            if i == 5:  # After circuit should be open
                time.sleep(0.1)

        # Verify circuit breaker opened after threshold
        circuit_breaker_events = [r for r in error_tracker.recovery_attempts if "circuit_breaker" in r["strategy"]]
        opened_events = [e for e in circuit_breaker_events if "opened" in e["strategy"]]
        assert len(opened_events) > 0, "Circuit breaker should have opened"

        # Should have blocked some calls
        blocked_calls = [f for f in error_tracker.fallback_attempts if "blocked_call" in f["fallback"]]
        assert len(blocked_calls) > 0, "Circuit breaker should have blocked calls"

        # Wait for recovery timeout
        time.sleep(0.6)

        # Test recovery phase - service should now succeed
        recovery_attempts = 0
        for recovery_attempts in range(1, 4):
            try:
                result = circuit_breaker.call(service.make_request)
                results.append(result)
                error_tracker.track_recovery(
                    "circuit_breaker_recovery_success", success=True, attempt_count=recovery_attempts
                )
                break  # Success should close circuit
            except (ConnectionError, RuntimeError) as e:
                exceptions.append(str(e))

        # Verify circuit eventually closed and recovered
        recovery_events = [r for r in error_tracker.recovery_attempts if "recovery_success" in r["strategy"]]
        assert len(recovery_events) > 0, "Circuit breaker should have recovered"
        assert len(results) > 0, "Should have some successful results"
